Workbook

Sheet Profile & FIRE Plan
B2: FIRE PLAN — 25-Year-Old · ₹5 Lakh Annual Salary 🇮🇳
B3: Yellow cells = your inputs · Blue cells = auto-calculated · Change yellow cells and everything recalculates automatically
B5: A. YOUR INCOME BREAKDOWN
B6: Item | C6: Amount (₹) | D6: Calculation | E6: Note
B7: Annual CTC (Cost to Company) | C7: 500000 | D7: =C7 | E7: Your total annual package
B8: Annual EPF — Employee 12% | C8: =C7*0.12/12*12 | D8: =C7×12% | E8: Auto-deducted; goes to your EPF account
B9: Estimated Annual Tax (old regime) | C9: =MAX(C7-250000,0)*0.05 | D9: 5% on ₹2.5L+ | E9: ₹0–2.5L nil, ₹2.5L–5L at 5%
B10: Annual Take-Home (Net) | C10: =C7-C8-C9 | D10: =CTC−EPF−Tax | E10: Actual money hitting your bank
B11: Monthly Take-Home | C11: =C10/12 | D11: =C10÷12 | E11: What you work with each month
B13: B. MONTHLY BUDGET ALLOCATION (out of ₹ in-hand)
B14: FIXED EXPENSES · Category | C14: Budget (₹/mo) | D14: % of Income | E14: Annual (₹) | F14: Remarks
B15: Rent (shared / PG) | C15: 8000 | D15: =IF(C11>0,C15/C11,0) | E15: =C15*12 | F15: Shared accommodation saves big
B16: Electricity, Water & Gas | C16: 800 | D16: =IF(C11>0,C16/C11,0) | E16: =C16*12
B17: Mobile + Internet | C17: 1000 | D17: =IF(C11>0,C17/C11,0) | E17: =C17*12 | F17: ₹400 SIM + ₹600 broadband
B18: Health Insurance Premium | C18: 1500 | D18: =IF(C11>0,C18/C11,0) | E18: =C18*12 | F18: ₹5L cover ~ ₹1500/mo
B19: Term Life Insurance | C19: 500 | D19: =IF(C11>0,C19/C11,0) | E19: =C19*12 | F19: ₹1Cr cover ~ ₹6000/yr at 25
B20: OTT / Subscriptions | C20: 500 | D20: =IF(C11>0,C20/C11,0) | E20: =C20*12 | F20: Netflix, Spotify etc.
B21: TOTAL FIXED EXPENSES | C21: =SUM(C15:C20) | D21: =IF(C11>0,C21/C11,0) | E21: =C21*12
B22: VARIABLE EXPENSES · Category | C22: Budget (₹/mo) | D22: % of Income | E22: Annual (₹) | F22: Remarks
B23: Groceries & Kirana | C23: 3000 | D23: =IF(C11>0,C23/C11,0) | E23: =C23*12
B24: Dining Out / Zomato / Swiggy | C24: 2000 | D24: =IF(C11>0,C24/C11,0) | E24: =C24*12 | F24: Limit this — huge savings lever
B25: Petrol / Auto / Metro | C25: 2000 | D25: =IF(C11>0,C25/C11,0) | E25: =C25*12
B26: Clothing & Shopping | C26: 1500 | D26: =IF(C11>0,C26/C11,0) | E26: =C26*12
B27: Medical / Pharmacy | C27: 1000 | D27: =IF(C11>0,C27/C11,0) | E27: =C27*12
B28: Entertainment & Outings | C28: 1500 | D28: =IF(C11>0,C28/C11,0) | E28: =C28*12
B29: Miscellaneous | C29: 1200 | D29: =IF(C11>0,C29/C11,0) | E29: =C29*12
B30: TOTAL VARIABLE EXPENSES | C30: =SUM(C23:C29) | D30: =IF(C11>0,C30/C11,0) | E30: =C30*12
B31: SAVINGS & INVESTMENTS ← FIRE ENGINE · Category | C31: Budget (₹/mo) | D31: % of Income | E31: Annual (₹) | F31: Remarks
B32: SIP — Equity Mutual Fund (Nifty 50) | C32: 5000 | D32: =IF(C11>0,C32/C11,0) | E32: =C32*12 | F32: Core FIRE investment
B33: PPF Contribution | C33: 1000 | D33: =IF(C11>0,C33/C11,0) | E33: =C33*12 | F33: Tax-free, 7.1% guaranteed
B34: Emergency Fund / Liquid FD | C34: 500 | D34: =IF(C11>0,C34/C11,0) | E34: =C34*12 | F34: Build 3–6 months expenses first
B35: EPF — Employee Share (auto 12%) | C35: =C7*0.12/12 | D35: =IF(C11>0,C35/C11,0) | E35: =C35*12 | F35: Auto-deducted from salary; grows in your EPF account
B36: TOTAL MONTHLY SAVINGS | C36: =SUM(C32:C35) | D36: =IF(C11>0,C36/C11,0) | E36: =C36*12
B37: C. FIRE ASSUMPTIONS (change yellow cells)
B38: Assumption | C38: Value | D38: Formula / Logic | F38: Note
B39: Current Age | C39: 25 | F39: Edit this
B40: Monthly Investment (SIP + EPF + PPF) | C40: =C36 | D40: =SUM of savings above | F40: All your investments combined
B41: Current Portfolio Value | C41: 0 | F41: 0 if just starting out
B42: Expected Annual Return | C42: 0.12 | D42: Nifty 50 CAGR ~12% | F42: Conservative = use 10%
B43: Annual Salary Increment Rate | C43: 0.08 | D43: Industry avg 8–10% | F43: Investment grows with salary
...

Sheet Year-by-Year Projection
B2: YEAR-BY-YEAR PROJECTION · 25yr Old · ₹5L Salary · Retire at 45
B3: Corpus formula: Opening Balance × (1+return) + Annual Investment · All values in ₹ · Return = 12% p.a. · Investment grows 8% p.a. with salary
B5: HOW THE FORMULA WORKS:
B6: Year-End Balance = (Opening Balance + Annual SIP) × (1 + Annual Return Rate) ↑ Same as compound interest but you keep adding money each year
B8: Yr | C8: Age | D8: Opening Balance (₹) | E8: Annual Investment (₹) | F8: Investment Return (₹) | G8: Year-End Corpus (₹) | H8: FIRE Target (₹) | I8: FI % Achieved
B9: 1 | C9: ='Profile & FIRE Plan'!C39+1 | D9: ='Profile & FIRE Plan'!C41 | E9: ='Profile & FIRE Plan'!C40*12*(1+'Profile & FIRE Plan'!C43)^0 | F9: =(D9+E9/2)*'Profile & FIRE Plan'!C42 | G9: =D9+E9+F9 | H9: ='Profile & FIRE Plan'!C47 | I9: =IF(H9>0,MIN(G9/H9,2),0)
B10: 2 | C10: ='Profile & FIRE Plan'!C39+2 | D10: =G9 | E10: ='Profile & FIRE Plan'!C40*12*(1+'Profile & FIRE Plan'!C43)^1 | F10: =(D10+E10/2)*'Profile & FIRE Plan'!C42 | G10: =D10+E10+F10 | H10: ='Profile & FIRE Plan'!C47 | I10: =IF(H10>0,MIN(G10/H10,2),0)
B11: 3 | C11: ='Profile & FIRE Plan'!C39+3 | D11: =G10 | E11: ='Profile & FIRE Plan'!C40*12*(1+'Profile & FIRE Plan'!C43)^2 | F11: =(D11+E11/2)*'Profile & FIRE Plan'!C42 | G11: =D11+E11+F11 | H11: ='Profile & FIRE Plan'!C47 | I11: =IF(H11>0,MIN(G11/H11,2),0)
B12: 4 | C12: ='Profile & FIRE Plan'!C39+4 | D12: =G11 | E12: ='Profile & FIRE Plan'!C40*12*(1+'Profile & FIRE Plan'!C43)^3 | F12: =(D12+E12/2)*'Profile & FIRE Plan'!C42 | G12: =D12+E12+F12 | H12: ='Profile & FIRE Plan'!C47 | I12: =IF(H12>0,MIN(G12/H12,2),0)
B13: 5 | C13: ='Profile & FIRE Plan'!C39+5 | D13: =G12 | E13: ='Profile & FIRE Plan'!C40*12*(1+'Profile & FIRE Plan'!C43)^4 | F13: =(D13+E13/2)*'Profile & FIRE Plan'!C42 | G13: =D13+E13+F13 | H13: ='Profile & FIRE Plan'!C47 | I13: =IF(H13>0,MIN(G13/H13,2),0)
B14: 6 | C14: ='Profile & FIRE Plan'!C39+6 | D14: =G13 | E14: ='Profile & FIRE Plan'!C40*12*(1+'Profile & FIRE Plan'!C43)^5 | F14: =(D14+E14/2)*'Profile & FIRE Plan'!C42 | G14: =D14+E14+F14 | H14: ='Profile & FIRE Plan'!C47 | I14: =IF(H14>0,MIN(G14/H14,2),0)
B15: 7 | C15: ='Profile & FIRE Plan'!C39+7 | D15: =G14 | E15: ='Profile & FIRE Plan'!C40*12*(1+'Profile & FIRE Plan'!C43)^6 | F15: =(D15+E15/2)*'Profile & FIRE Plan'!C42 | G15: =D15+E15+F15 | H15: ='Profile & FIRE Plan'!C47 | I15: =IF(H15>0,MIN(G15/H15,2),0)
B16: 8 | C16: ='Profile & FIRE Plan'!C39+8 | D16: =G15 | E16: ='Profile & FIRE Plan'!C40*12*(1+'Profile & FIRE Plan'!C43)^7 | F16: =(D16+E16/2)*'Profile & FIRE Plan'!C42 | G16: =D16+E16+F16 | H16: ='Profile & FIRE Plan'!C47 | I16: =IF(H16>0,MIN(G16/H16,2),0)
B17: 9 | C17: ='Profile & FIRE Plan'!C39+9 | D17: =G16 | E17: ='Profile & FIRE Plan'!C40*12*(1+'Profile & FIRE Plan'!C43)^8 | F17: =(D17+E17/2)*'Profile & FIRE Plan'!C42 | G17: =D17+E17+F17 | H17: ='Profile & FIRE Plan'!C47 | I17: =IF(H17>0,MIN(G17/H17,2),0)
B18: 10 | C18: ='Profile & FIRE Plan'!C39+10 | D18: =G17 | E18: ='Profile & FIRE Plan'!C40*12*(1+'Profile & FIRE Plan'!C43)^9 | F18: =(D18+E18/2)*'Profile & FIRE Plan'!C42 | G18: =D18+E18+F18 | H18: ='Profile & FIRE Plan'!C47 | I18: =IF(H18>0,MIN(G18/H18,2),0)
B19: 11 | C19: ='Profile & FIRE Plan'!C39+11 | D19: =G18 | E19: ='Profile & FIRE Plan'!C40*12*(1+'Profile & FIRE Plan'!C43)^10 | F19: =(D19+E19/2)*'Profile & FIRE Plan'!C42 | G19: =D19+E19+F19 | H19: ='Profile & FIRE Plan'!C47 | I19: =IF(H19>0,MIN(G19/H19,2),0)
B20: 12 | C20: ='Profile & FIRE Plan'!C39+12 | D20: =G19 | E20: ='Profile & FIRE Plan'!C40*12*(1+'Profile & FIRE Plan'!C43)^11 | F20: =(D20+E20/2)*'Profile & FIRE Plan'!C42 | G20: =D20+E20+F20 | H20: ='Profile & FIRE Plan'!C47 | I20: =IF(H20>0,MIN(G20/H20,2),0)
B21: 13 | C21: ='Profile & FIRE Plan'!C39+13 | D21: =G20 | E21: ='Profile & FIRE Plan'!C40*12*(1+'Profile & FIRE Plan'!C43)^12 | F21: =(D21+E21/2)*'Profile & FIRE Plan'!C42 | G21: =D21+E21+F21 | H21: ='Profile & FIRE Plan'!C47 | I21: =IF(H21>0,MIN(G21/H21,2),0)
B22: 14 | C22: ='Profile & FIRE Plan'!C39+14 | D22: =G21 | E22: ='Profile & FIRE Plan'!C40*12*(1+'Profile & FIRE Plan'!C43)^13 | F22: =(D22+E22/2)*'Profile & FIRE Plan'!C42 | G22: =D22+E22+F22 | H22: ='Profile & FIRE Plan'!C47 | I22: =IF(H22>0,MIN(G22/H22,2),0)
B23: 15 | C23: ='Profile & FIRE Plan'!C39+15 | D23: =G22 | E23: ='Profile & FIRE Plan'!C40*12*(1+'Profile & FIRE Plan'!C43)^14 | F23: =(D23+E23/2)*'Profile & FIRE Plan'!C42 | G23: =D23+E23+F23 | H23: ='Profile & FIRE Plan'!C47 | I23: =IF(H23>0,MIN(G23/H23,2),0)
B24: 16 | C24: ='Profile & FIRE Plan'!C39+16 | D24: =G23 | E24: ='Profile & FIRE Plan'!C40*12*(1+'Profile & FIRE Plan'!C43)^15 | F24: =(D24+E24/2)*'Profile & FIRE Plan'!C42 | G24: =D24+E24+F24 | H24: ='Profile & FIRE Plan'!C47 | I24: =IF(H24>0,MIN(G24/H24,2),0)
B25: 17 | C25: ='Profile & FIRE Plan'!C39+17 | D25: =G24 | E25: ='Profile & FIRE Plan'!C40*12*(1+'Profile & FIRE Plan'!C43)^16 | F25: =(D25+E25/2)*'Profile & FIRE Plan'!C42 | G25: =D25+E25+F25 | H25: ='Profile & FIRE Plan'!C47 | I25: =IF(H25>0,MIN(G25/H25,2),0)
B26: 18 | C26: ='Profile & FIRE Plan'!C39+18 | D26: =G25 | E26: ='Profile & FIRE Plan'!C40*12*(1+'Profile & FIRE Plan'!C43)^17 | F26: =(D26+E26/2)*'Profile & FIRE Plan'!C42 | G26: =D26+E26+F26 | H26: ='Profile & FIRE Plan'!C47 | I26: =IF(H26>0,MIN(G26/H26,2),0)
B27: 19 | C27: ='Profile & FIRE Plan'!C39+19 | D27: =G26 | E27: ='Profile & FIRE Plan'!C40*12*(1+'Profile & FIRE Plan'!C43)^18 | F27: =(D27+E27/2)*'Profile & FIRE Plan'!C42 | G27: =D27+E27+F27 | H27: ='Profile & FIRE Plan'!C47 | I27: =IF(H27>0,MIN(G27/H27,2),0)
B28: 20 | C28: ='Profile & FIRE Plan'!C39+20 | D28: =G27 | E28: ='Profile & FIRE Plan'!C40*12*(1+'Profile & FIRE Plan'!C43)^19 | F28: =(D28+E28/2)*'Profile & FIRE Plan'!C42 | G28: =D28+E28+F28 | H28: ='Profile & FIRE Plan'!C47 | I28: =IF(H28>0,MIN(G28/H28,2),0)
B29: 21 | C29: ='Profile & FIRE Plan'!C39+21 | D29: =G28 | E29: ='Profile & FIRE Plan'!C40*12*(1+'Profile & FIRE Plan'!C43)^20 | F29: =(D29+E29/2)*'Profile & FIRE Plan'!C42 | G29: =D29+E29+F29 | H29: ='Profile & FIRE Plan'!C47 | I29: =IF(H29>0,MIN(G29/H29,2),0)
B30: 22 | C30: ='Profile & FIRE Plan'!C39+22 | D30: =G29 | E30: ='Profile & FIRE Plan'!C40*12*(1+'Profile & FIRE Plan'!C43)^21 | F30: =(D30+E30/2)*'Profile & FIRE Plan'!C42 | G30: =D30+E30+F30 | H30: ='Profile & FIRE Plan'!C47 | I30: =IF(H30>0,MIN(G30/H30,2),0)
B31: 23 | C31: ='Profile & FIRE Plan'!C39+23 | D31: =G30 | E31: ='Profile & FIRE Plan'!C40*12*(1+'Profile & FIRE Plan'!C43)^22 | F31: =(D31+E31/2)*'Profile & FIRE Plan'!C42 | G31: =D31+E31+F31 | H31: ='Profile & FIRE Plan'!C47 | I31: =IF(H31>0,MIN(G31/H31,2),0)
B32: 24 | C32: ='Profile & FIRE Plan'!C39+24 | D32: =G31 | E32: ='Profile & FIRE Plan'!C40*12*(1+'Profile & FIRE Plan'!C43)^23 | F32: =(D32+E32/2)*'Profile & FIRE Plan'!C42 | G32: =D32+E32+F32 | H32: ='Profile & FIRE Plan'!C47 | I32: =IF(H32>0,MIN(G32/H32,2),0)
B33: 25 | C33: ='Profile & FIRE Plan'!C39+25 | D33: =G32 | E33: ='Profile & FIRE Plan'!C40*12*(1+'Profile & FIRE Plan'!C43)^24 | F33: =(D33+E33/2)*'Profile & FIRE Plan'!C42 | G33: =D33+E33+F33 | H33: ='Profile & FIRE Plan'!C47 | I33: =IF(H33>0,MIN(G33/H33,2),0)
B34: 26 | C34: ='Profile & FIRE Plan'!C39+26 | D34: =G33 | E34: ='Profile & FIRE Plan'!C40*12*(1+'Profile & FIRE Plan'!C43)^25 | F34: =(D34+E34/2)*'Profile & FIRE Plan'!C42 | G34: =D34+E34+F34 | H34: ='Profile & FIRE Plan'!C47 | I34: =IF(H34>0,MIN(G34/H34,2),0)
B35: 27 | C35: ='Profile & FIRE Plan'!C39+27 | D35: =G34 | E35: ='Profile & FIRE Plan'!C40*12*(1+'Profile & FIRE Plan'!C43)^26 | F35: =(D35+E35/2)*'Profile & FIRE Plan'!C42 | G35: =D35+E35+F35 | H35: ='Profile & FIRE Plan'!C47 | I35: =IF(H35>0,MIN(G35/H35,2),0)
B36: 28 | C36: ='Profile & FIRE Plan'!C39+28 | D36: =G35 | E36: ='Profile & FIRE Plan'!C40*12*(1+'Profile & FIRE Plan'!C43)^27 | F36: =(D36+E36/2)*'Profile & FIRE Plan'!C42 | G36: =D36+E36+F36 | H36: ='Profile & FIRE Plan'!C47 | I36: =IF(H36>0,MIN(G36/H36,2),0)
B37: 29 | C37: ='Profile & FIRE Plan'!C39+29 | D37: =G36 | E37: ='Profile & FIRE Plan'!C40*12*(1+'Profile & FIRE Plan'!C43)^28 | F37: =(D37+E37/2)*'Profile & FIRE Plan'!C42 | G37: =D37+E37+F37 | H37: ='Profile & FIRE Plan'!C47 | I37: =IF(H37>0,MIN(G37/H37,2),0)
B38: 30 | C38: ='Profile & FIRE Plan'!C39+30 | D38: =G37 | E38: ='Profile & FIRE Plan'!C40*12*(1+'Profile & FIRE Plan'!C43)^29 | F38: =(D38+E38/2)*'Profile & FIRE Plan'!C42 | G38: =D38+E38+F38 | H38: ='Profile & FIRE Plan'!C47 | I38: =IF(H38>0,MIN(G38/H38,2),0)
B39: 31 | C39: ='Profile & FIRE Plan'!C39+31 | D39: =G38 | E39: ='Profile & FIRE Plan'!C40*12*(1+'Profile & FIRE Plan'!C43)^30 | F39: =(D39+E39/2)*'Profile & FIRE Plan'!C42 | G39: =D39+E39+F39 | H39: ='Profile & FIRE Plan'!C47 | I39: =IF(H39>0,MIN(G39/H39,2),0)
B40: 32 | C40: ='Profile & FIRE Plan'!C39+32 | D40: =G39 | E40: ='Profile & FIRE Plan'!C40*12*(1+'Profile & FIRE Plan'!C43)^31 | F40: =(D40+E40/2)*'Profile & FIRE Plan'!C42 | G40: =D40+E40+F40 | H40: ='Profile & FIRE Plan'!C47 | I40: =IF(H40>0,MIN(G40/H40,2),0)
B41: 33 | C41: ='Profile & FIRE Plan'!C39+33 | D41: =G40 | E41: ='Profile & FIRE Plan'!C40*12*(1+'Profile & FIRE Plan'!C43)^32 | F41: =(D41+E41/2)*'Profile & FIRE Plan'!C42 | G41: =D41+E41+F41 | H41: ='Profile & FIRE Plan'!C47 | I41: =IF(H41>0,MIN(G41/H41,2),0)
B42: 34 | C42: ='Profile & FIRE Plan'!C39+34 | D42: =G41 | E42: ='Profile & FIRE Plan'!C40*12*(1+'Profile & FIRE Plan'!C43)^33 | F42: =(D42+E42/2)*'Profile & FIRE Plan'!C42 | G42: =D42+E42+F42 | H42: ='Profile & FIRE Plan'!C47 | I42: =IF(H42>0,MIN(G42/H42,2),0)
B43: 35 | C43: ='Profile & FIRE Plan'!C39+35 | D43: =G42 | E43: ='Profile & FIRE Plan'!C40*12*(1+'Profile & FIRE Plan'!C43)^34 | F43: =(D43+E43/2)*'Profile & FIRE Plan'!C42 | G43: =D43+E43+F43 | H43: ='Profile & FIRE Plan'!C47 | I43: =IF(H43>0,MIN(G43/H43,2),0)
...
